}
catch( exception &error_ )
{
cout << "Caught exception: " << error_.what() << endl;
return 1;
}

return 0;
}
